Workbook

Sheet 属性及攻击伤害
A1: 1级 | B1: 角色1：快速射击 | E1: 角色2：持续伤害 | H1: 角色3：范围伤害 | K1: 角色4：穿透 | N1: 2级 | O1: 角色1 | R1: 角色2 | U1: 角色3 | X1: 角色4
B2: 攻击 | C2: =7+C12 -> 7 | E2: 攻击 | F2: =6+C12 -> 6 | H2: 攻击 | I2: =8+C12 -> 8 | K2: 攻击 | L2: =6+C12 -> 6 | O2: 攻击 | P2: =C2+C2*P12 -> 9.8 | R2: 攻击 | S2: =F2+F2*S12 -> 9 | U2: 攻击 | V2: =I2+I2*V12 -> 12.4 | X2: 攻击 | Y2: =L2+L2*Y12 -> 7.8
B3: 暴击 | C3: =15%+C13 -> 0.15 | E3: 暴击 | F3: =12%+C13 -> 0.12 | H3: 暴击 | I3: =3%+C13 -> 0.03 | K3: 暴击 | L3: =20%+C13 -> 0.2 | O3: 暴击 | P3: =C3+P13 -> 0.2 | R3: 暴击 | S3: =F3+S13 -> 0.17 | U3: 暴击 | V3: =I3+V13 -> 0.03 | X3: 暴击 | Y3: =L3+Y13 -> 0.3
B4: 暴击伤害 | C4: =140%+C14 -> 1.4 | E4: 暴击伤害 | F4: =170%+C14 -> 1.7 | H4: 暴击伤害 | I4: =190%+C14 -> 1.9 | K4: 暴击伤害 | L4: =160%+C14 -> 1.6 | O4: 暴击伤害 | P4: =C4+P14 -> 1.7 | R4: 暴击伤害 | S4: =F4+S14 -> 1.85 | U4: 暴击伤害 | V4: =I4+V14 -> 2.2 | X4: 暴击伤害 | Y4: =L4+Y14 -> 1.6
B5: 速度(次/秒) | C5: 6 | E5: 速度(次/秒) | F5: 1 | H5: 速度(次/秒) | I5: 0.6 | K5: 速度(次/秒) | L5: 1.5 | O5: 速度(次/秒) | P5: =C5+P15 -> 6 | R5: 速度(次/秒) | S5: =F5+S15 -> 1 | U5: 速度(次/秒) | V5: =I5 -> 0.6 | X5: 速度(次/秒) | Y5: =L5+Y15 -> 1.5
B6: 状态触发间隔 | C6: 0 | E6: 状态触发间隔 | F6: 0.5 | H6: 状态触发间隔 | I6: 0 | K6: 状态触发间隔 | L6: 0 | O6: 状态触发间隔 | P6: 0 | R6: 状态触发间隔 | S6: 0.5 | U6: 状态触发间隔 | V6: =I6 -> 0 | X6: 状态触发间隔 | Y6: 0
B7: 伤害加深 | C7: =1+C16 -> 1 | E7: 伤害加深 | F7: =130%+C16 -> 1.3 | H7: 伤害加深 | I7: =1+C16 -> 1 | K7: 伤害加深 | L7: =1+C16 -> 1 | O7: 伤害加深 | P7: =C7+P16 -> 1 | R7: 伤害加深 | S7: =F7+S16 -> 1.3 | U7: 伤害加深 | V7: =I7 -> 1 | X7: 伤害加深 | Y7: =L7+Y16 -> 1
B8: 伤害范围 | C8: 1 | E8: 伤害范围 | F8: 3 | H8: 伤害范围 | I8: 5 | K8: 伤害范围 | L8: 1 | O8: 伤害范围 | P8: =C8+P17 -> 1 | R8: 伤害范围 | S8: =F8+S17 -> 3 | U8: 伤害范围 | V8: =I8 -> 5 | X8: 伤害范围 | Y8: =L8+Y17 -> 1
B9: 技能伤害 | C9: 0.5 | E9: 技能伤害 | F9: 0.4 | H9: 技能伤害 | I9: 1 | K9: 技能伤害 | L9: 2 | O9: 技能伤害 | P9: =C9 -> 0.5 | R9: 技能伤害 | S9: =F9 -> 0.4 | U9: 技能伤害 | V9: =I9 -> 1 | X9: 技能伤害 | Y9: =L9 -> 2
E10: 状态技能伤害 | F10: 0.3 | R10: 状态技能伤害 | S10: 0.3
B11: 天赋增加 | O11: 升级效果1
B12: 攻击 | C12: 0 | O12: 攻击力 | P12: 0.4 | S12: 0.5 | V12: 0.55 | Y12: 0.3
B13: 暴击 | C13: 0 | O13: 暴击 | P13: 0.05 | S13: 0.05 | Y13: 0.1
B14: 暴击伤害 | C14: 0 | O14: 暴击伤害 | P14: 0.3 | S14: 0.15 | V14: 0.3
B15: 速度 | C15: 0 | O15: 速度
B16: 伤害加深 | C16: 0 | O16: 伤害加深
O17: 伤害范围
B18: DPS | E18: DPS | H18: DPS | K18: DPS | O18: DPS | R18: DPS | U18: DPS | X18: DPS
B19: =C2*C9*(1+C3*C4)*C7*C5*C8 -> 25.41 | E19: =F2*F9*(1+F3*F4)*F7*F5*F8+F2*F10*F7*(1/F6)*F8 -> 25.30944 | H19: =I2*I9*(1+I3*I4)*I7*I5*I8 -> 25.368 | K19: =L2*L9*(1+L3*L4)*L7*L5*L8 -> 23.76 | O19: =P2*P9*(1+P3*P4)*P7*P5*P8 -> 39.396 | R19: =S2*S9*(1+S3*S4)*S7*S5*S8+S2*S10*S7*(1/S6)*S8 -> 39.51558 | U19: =V2*V9*(1+V3*V4)*V7*V5*V8 -> 39.6552 | X19: =Y2*Y9*(1+Y3*Y4)*Y7*Y5*Y8 -> 34.632
B20: =C5*C9*C8 -> 3 | E20: =(F9*F5+F10/F6)*F8 -> 3 | H20: =I9*I5*I8 -> 3 | K20: =L9*L5*L8 -> 3
B21: 每秒造成伤害= | C21: 攻击*技能伤害*(1+暴击率*暴击伤害)*伤害加深*攻击次数*伤害范围
A22: 3级 | B22: 角色1 | E22: 角色2 | H22: 角色3 | K22: 角色4 | N22: 4级 | O22: 角色1 | R22: 角色2 | U22: 角色3 | X22: 角色4
B23: 攻击 | C23: =P2 -> 9.8 | E23: 攻击 | F23: =S2 -> 9 | H23: 攻击 | I23: =V2 -> 12.4 | K23: 攻击 | L23: =Y2 -> 7.8 | O23: 攻击 | P23: =C2+C2*P34 -> 15.4 | R23: 攻击 | S23: =F2+F2*S34 -> 12.9 | U23: 攻击 | V23: =I2+I2*V34 -> 16 | X23: 攻击 | Y23: =L2+L2*Y34 -> 12.3
B24: 暴击 | C24: =P3 -> 0.2 | E24: 暴击 | F24: =S3 -> 0.17 | H24: 暴击 | I24: =V3 -> 0.03 | K24: 暴击 | L24: =Y3 -> 0.3 | O24: 暴击 | P24: =C24+P35 -> 0.3 | R24: 暴击 | S24: =F24+S35 -> 0.23 | U24: 暴击 | V24: =I24+V35 -> 0.03 | X24: 暴击 | Y24: =L24+Y35 -> 0.55
B25: 暴击伤害 | C25: =P4 -> 1.7 | E25: 暴击伤害 | F25: =S4 -> 1.85 | H25: 暴击伤害 | I25: =V4 -> 2.2 | K25: 暴击伤害 | L25: =Y4 -> 1.6 | O25: 暴击伤害 | P25: =C25+P36 -> 1.93 | R25: 暴击伤害 | S25: =F25+S36 -> 1.85 | U25: 暴击伤害 | V25: =I25+V36 -> 3 | X25: 暴击伤害 | Y25: =L25+Y36 -> 1.82
B26: 速度(次/秒) | C26: =P5 -> 6 | E26: 速度(次/秒) | F26: =S5 -> 1 | H26: 速度(次/秒) | I26: 1 | K26: 速度(次/秒) | L26: =Y5 -> 1.5 | O26: 速度(次/秒) | P26: =C26+P37 -> 6 | R26: 速度(次/秒) | S26: =F26+S37 -> 1 | U26: 速度(次/秒) | V26: =I26+V37 -> 1 | X26: 速度(次/秒) | Y26: =L26+Y37 -> 1.5
B27: 状态触发间隔 | C27: =P6 -> 0 | E27: 状态触发间隔 | F27: 0.25 | H27: 状态触发间隔 | I27: 0.5 | K27: 状态触发间隔 | L27: =Y6 -> 0 | O27: 状态触发间隔 | P27: =AC6 -> 0 | R27: 状态触发间隔 | S27: 0.25 | U27: 状态触发间隔 | V27: 0.5 | X27: 状态触发间隔 | Y27: =AL6 -> 0
B28: 伤害加深 | C28: =P7 -> 1 | E28: 伤害加深 | F28: =S7 -> 1.3 | H28: 伤害加深 | I28: =V7 -> 1 | K28: 伤害加深 | L28: =Y7 -> 1 | O28: 伤害加深 | P28: =C28+P38 -> 1.05 | R28: 伤害加深 | S28: =F28+S38 -> 1.45 | U28: 伤害加深 | V28: =I28+V38 -> 1 | X28: 伤害加深 | Y28: =L28+Y38 -> 1
B29: 伤害范围 | C29: =P8 -> 1 | E29: 伤害范围 | F29: 2 | H29: 伤害范围 | I29: =V8 -> 5 | K29: 伤害范围 | L29: 1 | O29: 伤害范围 | P29: =C29+P39 -> 1 | R29: 伤害范围 | S29: =F29+S39 -> 2 | U29: 伤害范围 | V29: =I29+V39 -> 5 | X29: 伤害范围 | Y29: =L29+Y39 -> 1
B30: 技能伤害 | C30: =P9 -> 0.5 | E30: 技能伤害 | F30: =S9 -> 0.4 | H30: 技能伤害 | I30: =V9 -> 1 | K30: 技能伤害 | L30: =Y9 -> 2 | O30: 技能伤害 | P30: =C30 -> 0.5 | R30: 技能伤害 | S30: 0.45 | U30: 技能伤害 | V30: =I30 -> 1 | X30: 技能伤害 | Y30: =L30 -> 2
B31: 被动技能伤害 | C31: 1.6 | E31: 状态技能伤害 | F31: =S10 -> 0.3 | H31: 状态技能伤害 | I31: 0.3 | O31: 被动技能伤害 | P31: =C31 -> 1.6 | R31: 状态技能伤害 | S31: 0.3 | U31: 状态技能伤害 | V31: =I31 -> 0.3
B33: 升级效果2 | O33: 升级效果3
B34: 每5次攻击后，你的下一次普攻会向面前发出一道攻击范围为5的冲击波,每次触发冲击波后，使你造成的伤害提升15%，持续3秒 | E34: Buff附带减速效果，状态触发间隔变为0.25秒/次，并使目标受到的伤害加深20% | H34: 发出的炮弹爆炸的地方会留下一圈范围为5的火焰地面，对经过的敌人造成持续5秒的灼烧伤害，期间敌人受到的暴击伤害提高25% | K34: 箭矢击中目标时会分裂成2只小箭，每只小箭造成伤害为原伤害的25%，并使被击中的目标受到暴击的概率提升20% | O34: 攻击力 | P34: 1.2 | S34: 1.15 | V34: 1 | Y34: 1.05
O35: 暴击 | P35: 0.1 | S35: 0.06 | Y35: 0.25
O36: 暴击伤害 | P36: 0.23 | V36: 0.8 | Y36: 0.22
O37: 速度
O38: 伤害加深 | P38: 0.05 | S38: 0.15
O39: 伤害范围
A40: 附加效果 | N40: 附加效果
B41: =(C23*C31*(1+C24*C25)*C28*0.2)*3 -> 12.60672 | E41: 0.2 | H41: =I23*I31*(1+I24*I25)*(1/I27)*3 -> 23.79312 | K41: =X19*0.25*2 -> 17.316 | O41: =(P23*P31*(1+P24*P25)*P28*0.2)*3 -> 24.511133 | R41: 0.2 | U41: =V23*V31*(1+V24*V25)*(1/V27)*2 -> 20.928 | X41: =0.2*2*Y23*Y30*(1+Y24*Y25)*Y28*Y26*Y29 -> 29.53476
...

Sheet 天赋设定
A1: 天赋等级 | B1: 攻击力 | C1: 暴击 | D1: 暴伤 | E1: 伤害加深 | F1: 解锁所需金币 | G1: 预期解锁时间 | H1: 特殊天赋类型 | I1: 解锁所需金币 | J1: 预期解锁时间
A2: 1 | B2: 3 | F2: 100 | G2: =ROUNDUP(F2/金币收益!$B$4,3) -> 0.016 | H2: /
A3: 2 | C3: 1 | F3: =F2+A3*10 -> 120 | G3: =ROUNDUP(G2+F3/金币收益!$B$4,3) -> 0.035 | H3: /
A4: 3 | D4: 2 | F4: =F3+A4*10 -> 150 | G4: =ROUNDUP(G3+F4/金币收益!$B$4,3) -> 0.058 | H4: /
A5: 4 | B5: 4 | F5: =F4+A5*10 -> 190 | G5: =ROUNDUP(G4+F5/金币收益!$B$4,3) -> 0.087 | H5: /
A6: 5 | C6: 1 | F6: =F5+A6*10 -> 240 | G6: =ROUNDUP(G5+F6/金币收益!$B$4,3) -> 0.124 | H6: 基地健康度+5 | I6: =SUM(F2:F6)/2 -> 400 | J6: =ROUNDUP(G6+I6/金币收益!$B$4,3) -> 0.185
A7: 6 | E7: 7 | F7: =F6+A7*10 -> 300 | G7: =ROUNDUP(G6+F7/金币收益!$B$4,3) -> 0.17 | H7: /
A8: 7 | B8: 4 | F8: =F7+A8*10 -> 370 | G8: =ROUNDUP(G7+F8/金币收益!$B$4,3) -> 0.226 | H8: /
A9: 8 | C9: 1 | F9: =F8+A9*10 -> 450 | G9: =ROUNDUP(G8+F9/金币收益!$B$4,3) -> 0.294 | H9: /
A10: 9 | D10: 3 | F10: =F9+A10*10 -> 540 | G10: =ROUNDUP(G9+F10/金币收益!$B$4,3) -> 0.376 | H10: /
A11: 10 | B11: 4 | F11: =F10+A11*10 -> 640 | G11: =ROUNDUP(G10+F11/金币收益!$B$4,3) -> 0.473 | H11: 角色技能充能速度+1点/s | I11: =SUM(F7:F11)/2 -> 1150 | J11: =ROUNDUP(G11+I11/金币收益!$B$4,3) -> 0.647
A12: 11 | C12: 1 | F12: =F11+A12*10 -> 750 | G12: =ROUNDUP(G11+F12/金币收益!$B$4,3) -> 0.587 | H12: /
A13: 12 | D13: 3 | F13: =F12+A13*10 -> 870 | G13: =ROUNDUP(G12+F13/金币收益!$B$4,3) -> 0.719 | H13: /
A14: 13 | B14: 5 | F14: =F13+A14*10 -> 1000 | G14: =ROUNDUP(G13+F14/金币收益!$B$4,3) -> 0.87 | H14: /
A15: 14 | C15: 1 | F15: =F14+A15*10 -> 1140 | G15: =ROUNDUP(G14+F15/金币收益!$B$4,3) -> 1.043 | H15: /
A16: 15 | E16: 8 | F16: =F15+A16*10 -> 1290 | G16: =ROUNDUP(G15+F16/金币收益!$B$4,3) -> 1.238 | H16: 角色技能CD-5s | I16: =SUM(F12:F16)/2 -> 2525 | J16: =ROUNDUP(G16+I16/金币收益!$B$4,3) -> 1.62
A17: 16 | B17: 5 | F17: =F16+A17*10 -> 1450 | G17: =ROUNDUP(G16+F17/金币收益!$B$4,3) -> 1.457 | H17: /
A18: 17 | C18: 1 | F18: =F17+A18*10 -> 1620 | G18: =ROUNDUP(G17+F18/金币收益!$B$4,3) -> 1.702 | H18: /
A19: 18 | D19: 4 | F19: =F18+A19*10 -> 1800 | G19: =ROUNDUP(G18+F19/金币收益!$B$4,3) -> 1.974 | H19: /
A20: 19 | B20: 5 | F20: =F19+A20*10 -> 1990 | G20: =ROUNDUP(G19+F20/金币收益!$B$4,3) -> 2.275 | H20: /
A21: 20 | C21: 1 | F21: =F20+A21*10 -> 2190 | G21: =ROUNDUP(G20+F21/金币收益!$B$4,3) -> 2.606 | H21: 状态持续时间+1s | I21: =SUM(F17:F21)/2 -> 4525 | J21: =ROUNDUP(G21+I21/金币收益!$B$4,3) -> 3.29
A22: 21 | F22: =F21+A22*10 -> 2400 | G22: =ROUNDUP(G21+F22/金币收益!$B$4,3) -> 2.969 | H22: /
A23: 22 | B23: 10 | F23: =F22+A23*10 -> 2620 | G23: =ROUNDUP(G22+F23/金币收益!$B$4,3) -> 3.365 | H23: /
A24: 23 | C24: 2 | F24: =F23+A24*10 -> 2850 | G24: =ROUNDUP(G23+F24/金币收益!$B$4,3) -> 3.796 | H24: /
A25: 24 | D25: 4 | F25: =F24+A25*10 -> 3090 | G25: =ROUNDUP(G24+F25/金币收益!$B$4,3) -> 4.263 | H25: /
A26: 25 | B26: 10 | F26: =F25+A26*10 -> 3340 | G26: =ROUNDUP(G25+F26/金币收益!$B$4,3) -> 4.768 | H26: 角色技能充能速度+1点/s | I26: =SUM(F22:F26)/2 -> 7150 | J26: =ROUNDUP(G26+I26/金币收益!$B$4,3) -> 5.848
A27: 26 | E27: 5 | F27: =F26+A27*10 -> 3600 | G27: =ROUNDUP(G26+F27/金币收益!$B$4,3) -> 5.312 | H27: /
A28: 27 | C28: 2 | F28: =F27+A28*10 -> 3870 | G28: =ROUNDUP(G27+F28/金币收益!$B$4,3) -> 5.897 | H28: /
A29: 28 | B29: 10 | F29: =F28+A29*10 -> 4150 | G29: =ROUNDUP(G28+F29/金币收益!$B$4,3) -> 6.524 | H29: /
A30: 29 | D30: 5 | F30: =F29+A30*10 -> 4440 | G30: =ROUNDUP(G29+F30/金币收益!$B$4,3) -> 7.195 | H30: /
A31: 30 | C31: 2 | F31: =F30+A31*10 -> 4740 | G31: =ROUNDUP(G30+F31/金币收益!$B$4,3) -> 7.911 | H31: 基地健康值+10点 | I31: =SUM(F27:F31)/2 -> 10400 | J31: =ROUNDUP(G31+I31/金币收益!$B$4,3) -> 9.482
A32: 31 | B32: 10 | F32: =F31+A32*10 -> 5050 | G32: =ROUNDUP(G31+F32/金币收益!$B$4,3) -> 8.674 | H32: /
A33: 32 | D33: 5 | F33: =F32+A33*10 -> 5370 | G33: =ROUNDUP(G32+F33/金币收益!$B$4,3) -> 9.485 | H33: /
A34: 33 | C34: 2 | F34: =F33+A34*10 -> 5700 | G34: =ROUNDUP(G33+F34/金币收益!$B$4,3) -> 10.346 | H34: /
A35: 34 | B35: 10 | F35: =F34+A35*10 -> 6040 | G35: =ROUNDUP(G34+F35/金币收益!$B$4,3) -> 11.258 | H35: /
A36: 35 | E36: 5 | F36: =F35+A36*10 -> 6390 | G36: =ROUNDUP(G35+F36/金币收益!$B$4,3) -> 12.223 | H36: 角色技能充能速度+2点/s | I36: =SUM(F32:F36)/2 -> 14275 | J36: =ROUNDUP(G36+I36/金币收益!$B$4,3) -> 14.379
A37: 36 | C37: 2 | F37: =F36+A37*10 -> 6750 | G37: =ROUNDUP(G36+F37/金币收益!$B$4,3) -> 13.243 | H37: /
A38: 37 | B38: 10 | F38: =F37+A38*10 -> 7120 | G38: =ROUNDUP(G37+F38/金币收益!$B$4,3) -> 14.318 | H38: /
A39: 38 | D39: 5 | F39: =F38+A39*10 -> 7500 | G39: =ROUNDUP(G38+F39/金币收益!$B$4,3) -> 15.451 | H39: /
A40: 39 | C40: 2 | F40: =F39+A40*10 -> 7890 | G40: =ROUNDUP(G39+F40/金币收益!$B$4,3) -> 16.643 | H40: /
...

Sheet 关卡模式怪物属性
A1: 关卡数/波次 | B1: 1 | D1: 2 | F1: 3 | H1: 4 | J1: 5 | L1: 6 | N1: 7 | P1: 8 | R1: 9 | T1: 10
A2: 单人 | B2: 小怪数量 | C2: 小怪血量 | D2: 小怪数量 | E2: 小怪血量 | F2: 小怪数量 | G2: 小怪血量 | H2: 小怪数量 | I2: 小怪血量 | J2: 小怪数量 | K2: 小怪血量 | L2: 小怪数量 | M2: 小怪血量 | N2: 小怪数量 | O2: 小怪血量 | P2: 小怪数量 | Q2: 小怪血量 | R2: 小怪数量 | S2: 小怪血量 | T2: 精英数量 | U2: 精英血量 | V2: 衰减血量 | W2: BOSS数量 | X2: BOSS血量 | Z2: 成长倍率+总伤需求预期
A3: 1 | B3: 20 | C3: =ROUNDDOWN((天赋设定!C65*30)*0.7/B3,0) -> 26 | D3: 22 | E3: =ROUNDDOWN((天赋设定!C66*30)*0.7/D3,0) -> 37 | F3: 24 | G3: =ROUNDDOWN((天赋设定!C67*30)*0.7/F3,0) -> 52 | H3: 26 | I3: =ROUNDDOWN((天赋设定!C68*30)*0.7/H3,0) -> 93 | J3: 28 | K3: =ROUNDDOWN((30*天赋设定!C69)*0.7/J3,0) -> 118 | L3: 30 | M3: =ROUNDDOWN((30*136)*0.75/L3,0) -> 102 | N3: 30 | O3: =ROUNDDOWN((20*294)*0.8/N3,0) -> 156 | P3: 30 | Q3: =ROUNDDOWN((20*294)*0.85/P3,0) -> 166 | R3: 30 | S3: =ROUNDDOWN((20*426)*0.9/R3,0) -> 255 | T3: 2 | U3: =(K3*J3/2)*0.7 -> 1156.4 | V3: =ROUNDDOWN(U3*1400/2400,0) -> 674 | W3: 0 | AB3: 1
A4: 2 | B4: 20 | C4: =ROUNDUP(C3*(1+$Z$6),0) -> 34 | D4: 22 | E4: =ROUNDUP(E3*(1+$Z$6),0) -> 49 | F4: 24 | G4: =ROUNDUP(G3*(1+$Z$6),0) -> 68 | H4: 26 | I4: =ROUNDUP(I3*(1+$Z$6),0) -> 121 | J4: 28 | K4: =ROUNDUP(K3*(1+$Z$6),0) -> 154 | L4: 30 | M4: =ROUNDUP(M3*(1+0.1),0) -> 113 | N4: 30 | O4: =ROUNDUP(O3*(1+0.1),0) -> 172 | P4: 30 | Q4: =ROUNDUP(Q3*(1+0.1),0) -> 183 | R4: 30 | S4: =ROUNDUP(S3*(1+0.1),0) -> 281 | T4: 2 | U4: =ROUNDUP(U3*(1+$Z$6),0) -> 1504 | V4: =ROUNDDOWN(U4*2000/2400,0) -> 1253 | W4: 0 | AB4: =ROUNDUP(E4/$E$3,3) -> 1.325
A5: 3 | B5: 20 | C5: =ROUNDUP(C4*(1+$Z$6),0) -> 45 | D5: 22 | E5: =ROUNDUP(E4*(1+$Z$6),0) -> 64 | F5: 24 | G5: =ROUNDUP(G4*(1+$Z$6),0) -> 89 | H5: 26 | I5: =ROUNDUP(I4*(1+$Z$6),0) -> 158 | J5: 28 | K5: =ROUNDUP(K4*(1+$Z$6),0) -> 201 | L5: 30 | M5: =ROUNDUP(M4*(1+0.1),0) -> 125 | N5: 30 | O5: =ROUNDUP(O4*(1+0.1),0) -> 190 | P5: 30 | Q5: =ROUNDUP(Q4*(1+0.1),0) -> 202 | R5: 30 | S5: =ROUNDUP(S4*(1+0.1),0) -> 310 | T5: 2 | U5: =ROUNDUP(U4*(1+$Z$6),0) -> 1956 | V5: =ROUNDDOWN(U5*2400/2400,0) -> 1956 | W5: 0 | AB5: =ROUNDUP(E5/$E$3,3) -> 1.73
A6: 4 | B6: 20 | C6: =ROUNDUP(C5*(1+$Z$6),0) -> 59 | D6: 22 | E6: =ROUNDUP(E5*(1+$Z$6),0) -> 84 | F6: 24 | G6: =ROUNDUP(G5*(1+$Z$6),0) -> 116 | H6: 26 | I6: =ROUNDUP(I5*(1+$Z$6),0) -> 206 | J6: 28 | K6: =ROUNDUP(K5*(1+$Z$6),0) -> 262 | L6: 30 | M6: =ROUNDUP(M5*(1+0.1),0) -> 138 | N6: 30 | O6: =ROUNDUP(O5*(1+0.1),0) -> 209 | P6: 30 | Q6: =ROUNDUP(Q5*(1+0.1),0) -> 223 | R6: 30 | S6: =ROUNDUP(S5*(1+0.1),0) -> 341 | T6: 2 | U6: =ROUNDUP(U5*(1+$Z$6),0) -> 2543 | V6: =ROUNDDOWN(U6*2400/2400,0) -> 2543 | W6: 0 | Z6: 0.3 | AB6: =ROUNDUP(E6/$E$3,3) -> 2.271
A7: 5 | B7: 20 | C7: =ROUNDUP(C6*(1+$Z$6),0) -> 77 | D7: 22 | E7: =ROUNDUP(E6*(1+$Z$6),0) -> 110 | F7: 24 | G7: =ROUNDUP(G6*(1+$Z$6),0) -> 151 | H7: 26 | I7: =ROUNDUP(I6*(1+$Z$6),0) -> 268 | J7: 28 | K7: =ROUNDUP(K6*(1+$Z$6),0) -> 341 | L7: 30 | M7: =ROUNDUP(M6*(1+0.1),0) -> 152 | N7: 30 | O7: =ROUNDUP(O6*(1+0.1),0) -> 230 | P7: 30 | Q7: =ROUNDUP(Q6*(1+0.1),0) -> 246 | R7: 30 | S7: =ROUNDUP(S6*(1+0.1),0) -> 376 | T7: 0 | U7: =ROUNDUP(U6*(1+$Z$6),0) -> 3306 | V7: =ROUNDDOWN(U7*2400/2400,0) -> 3306 | W7: 1 | X7: =V7*2 -> 6612 | Z7: =天赋设定!D69*20 -> 6761.8399 | AB7: =ROUNDUP(E7/$E$3,3) -> 2.973
A8: 6 | B8: 20 | C8: =ROUNDDOWN((天赋设定!D65*30)*0.7/$B$3,0) -> 89 | D8: 22 | E8: =ROUNDDOWN((天赋设定!D66*30)*0.7/D8,0) -> 102 | F8: 24 | G8: =ROUNDDOWN((天赋设定!D67*30)*0.7/$B$3,0) -> 170 | H8: 26 | I8: =ROUNDDOWN((天赋设定!D73*30)*0.7/$B$3,0) -> 253 | J8: 28 | K8: =ROUNDDOWN((天赋设定!D69*30)*0.7/$B$3,0) -> 354 | L8: 30 | M8: =ROUNDUP(M7*(1+0.1),0) -> 168 | N8: 30 | O8: =ROUNDUP(O7*(1+0.1),0) -> 253 | P8: 30 | Q8: =ROUNDUP(Q7*(1+0.1),0) -> 271 | R8: 30 | S8: =ROUNDUP(S7*(1+0.1),0) -> 414 | T8: 2 | U8: =(K8*J8/2)*0.7 -> 3469.2 | V8: =ROUNDDOWN(U8*2400/2400,0) -> 3469 | W8: 0 | AB8: =ROUNDUP(E8/$E$3,3) -> 2.757
A9: 7 | B9: 20 | C9: =ROUNDUP(C8*(1+$Z$11),0) -> 102 | D9: 22 | E9: =ROUNDUP(E8*(1+$Z$11),0) -> 117 | F9: 24 | G9: =ROUNDUP(G8*(1+$Z$11),0) -> 195 | H9: 26 | I9: =ROUNDUP(I8*(1+$Z$11),0) -> 290 | J9: 28 | K9: =ROUNDUP(K8*(1+$Z$11),0) -> 406 | L9: 30 | M9: =ROUNDUP(M8*(1+0.1),0) -> 185 | N9: 30 | O9: =ROUNDUP(O8*(1+0.1),0) -> 279 | P9: 30 | Q9: =ROUNDUP(Q8*(1+0.1),0) -> 299 | R9: 30 | S9: =ROUNDUP(S8*(1+0.1),0) -> 456 | T9: 2 | U9: =ROUNDUP(U8*(1+$Z$11),0) -> 3973 | V9: =ROUNDDOWN(U9*2400/2400,0) -> 3973 | W9: 0 | AB9: =ROUNDUP(E9/$E$3,3) -> 3.163
A10: 8 | B10: 20 | C10: =ROUNDUP(C9*(1+$Z$11),0) -> 117 | D10: 22 | E10: =ROUNDUP(E9*(1+$Z$11),0) -> 134 | F10: 24 | G10: =ROUNDUP(G9*(1+$Z$11),0) -> 224 | H10: 26 | I10: =ROUNDUP(I9*(1+$Z$11),0) -> 333 | J10: 28 | K10: =ROUNDUP(K9*(1+$Z$11),0) -> 465 | L10: 30 | M10: =ROUNDUP(M9*(1+0.1),0) -> 204 | N10: 30 | O10: =ROUNDUP(O9*(1+0.1),0) -> 307 | P10: 30 | Q10: =ROUNDUP(Q9*(1+0.1),0) -> 329 | R10: 30 | S10: =ROUNDUP(S9*(1+0.1),0) -> 502 | T10: 2 | U10: =ROUNDUP(U9*(1+$Z$11),0) -> 4550 | V10: =ROUNDDOWN(U10*2400/2400,0) -> 4550 | W10: 0 | AB10: =ROUNDUP(E10/$E$3,3) -> 3.622
A11: 9 | B11: 20 | C11: =ROUNDUP(C10*(1+$Z$11),0) -> 134 | D11: 22 | E11: =ROUNDUP(E10*(1+$Z$11),0) -> 154 | F11: 24 | G11: =ROUNDUP(G10*(1+$Z$11),0) -> 257 | H11: 26 | I11: =ROUNDUP(I10*(1+$Z$11),0) -> 382 | J11: 28 | K11: =ROUNDUP(K10*(1+$Z$11),0) -> 533 | L11: 30 | M11: =ROUNDUP(M10*(1+0.1),0) -> 225 | N11: 30 | O11: =ROUNDUP(O10*(1+0.1),0) -> 338 | P11: 30 | Q11: =ROUNDUP(Q10*(1+0.1),0) -> 362 | R11: 30 | S11: =ROUNDUP(S10*(1+0.1),0) -> 553 | T11: 2 | U11: =ROUNDUP(U10*(1+$Z$11),0) -> 5210 | V11: =ROUNDDOWN(U11*2400/2400,0) -> 5210 | W11: 0 | Z11: 0.145 | AB11: =ROUNDUP(E11/$E$3,3) -> 4.163
A12: 10 | B12: 20 | C12: =ROUNDUP(C11*(1+$Z$11),0) -> 154 | D12: 22 | E12: =ROUNDUP(E11*(1+$Z$11),0) -> 177 | F12: 24 | G12: =ROUNDUP(G11*(1+$Z$11),0) -> 295 | H12: 26 | I12: =ROUNDUP(I11*(1+$Z$11),0) -> 438 | J12: 28 | K12: =ROUNDUP(K11*(1+$Z$11),0) -> 611 | L12: 30 | M12: =ROUNDUP(M11*(1+0.1),0) -> 248 | N12: 30 | O12: =ROUNDUP(O11*(1+0.1),0) -> 372 | P12: 30 | Q12: =ROUNDUP(Q11*(1+0.1),0) -> 399 | R12: 30 | S12: =ROUNDUP(S11*(1+0.1),0) -> 609 | T12: 0 | U12: =ROUNDUP(U11*(1+$Z$11),0) -> 5966 | V12: =ROUNDDOWN(U12*2400/2400,0) -> 5966 | W12: 1 | X12: =V12*2 -> 11932 | Z12: =天赋设定!E69*20 -> 12048.957 | AB12: =ROUNDUP(E12/$E$3,3) -> 4.784
A13: 11 | B13: 20 | C13: =ROUNDDOWN((天赋设定!E65*30)*0.7/$B$3,0) -> 180 | D13: 22 | E13: =ROUNDDOWN((天赋设定!E66*30)*0.7/D13,0) -> 197 | F13: 24 | G13: =ROUNDDOWN((天赋设定!E67*30)*0.7/$B$3,0) -> 329 | H13: 26 | I13: =ROUNDDOWN((天赋设定!E68*30)*0.7/$B$3,0) -> 463 | J13: 28 | K13: =ROUNDDOWN((天赋设定!E69*30)*0.7/$B$3,0) -> 632 | L13: 30 | M13: =ROUNDUP(M12*(1+0.1),0) -> 273 | N13: 30 | O13: =ROUNDUP(O12*(1+0.1),0) -> 410 | P13: 30 | Q13: =ROUNDUP(Q12*(1+0.1),0) -> 439 | R13: 30 | S13: =ROUNDUP(S12*(1+0.1),0) -> 670 | T13: 2 | U13: =(K13*J13/2)*0.7 -> 6193.6 | V13: =ROUNDDOWN(U13*2400/2400,0) -> 6193 | W13: 0 | AB13: =ROUNDUP(E13/$E$3,3) -> 5.325
A14: 12 | B14: 20 | C14: =ROUNDUP(C13*(1+$Z$16),0) -> 207 | D14: 22 | E14: =ROUNDUP(E13*(1+$Z$16),0) -> 226 | F14: 24 | G14: =ROUNDUP(G13*(1+$Z$16),0) -> 377 | H14: 26 | I14: =ROUNDUP(I13*(1+$Z$16),0) -> 531 | J14: 28 | K14: =ROUNDUP(K13*(1+$Z$16),0) -> 724 | L14: 30 | M14: =ROUNDUP(M13*(1+0.1),0) -> 301 | N14: 30 | O14: =ROUNDUP(O13*(1+0.1),0) -> 451 | P14: 30 | Q14: =ROUNDUP(Q13*(1+0.1),0) -> 483 | R14: 30 | S14: =ROUNDUP(S13*(1+0.1),0) -> 737 | T14: 2 | U14: =ROUNDUP(U13*(1+$Z$16),0) -> 7092 | V14: =ROUNDDOWN(U14*2400/2400,0) -> 7092 | W14: 0 | AB14: =ROUNDUP(E14/$E$3,3) -> 6.109
A15: 13 | B15: 20 | C15: =ROUNDUP(C14*(1+$Z$16),0) -> 238 | D15: 22 | E15: =ROUNDUP(E14*(1+$Z$16),0) -> 259 | F15: 24 | G15: =ROUNDUP(G14*(1+$Z$16),0) -> 432 | H15: 26 | I15: =ROUNDUP(I14*(1+$Z$16),0) -> 608 | J15: 28 | K15: =ROUNDUP(K14*(1+$Z$16),0) -> 829 | L15: 30 | M15: =ROUNDUP(M14*(1+0.1),0) -> 332 | N15: 30 | O15: =ROUNDUP(O14*(1+0.1),0) -> 497 | P15: 30 | Q15: =ROUNDUP(Q14*(1+0.1),0) -> 532 | R15: 30 | S15: =ROUNDUP(S14*(1+0.1),0) -> 811 | T15: 2 | U15: =ROUNDUP(U14*(1+$Z$16),0) -> 8121 | V15: =ROUNDDOWN(U15*2400/2400,0) -> 8121 | W15: 0 | AB15: =ROUNDUP(E15/$E$3,3) -> 7
A16: 14 | B16: 20 | C16: =ROUNDUP(C15*(1+$Z$16),0) -> 273 | D16: 22 | E16: =ROUNDUP(E15*(1+$Z$16),0) -> 297 | F16: 24 | G16: =ROUNDUP(G15*(1+$Z$16),0) -> 495 | H16: 26 | I16: =ROUNDUP(I15*(1+$Z$16),0) -> 697 | J16: 28 | K16: =ROUNDUP(K15*(1+$Z$16),0) -> 950 | L16: 30 | M16: =ROUNDUP(M15*(1+0.1),0) -> 366 | N16: 30 | O16: =ROUNDUP(O15*(1+0.1),0) -> 547 | P16: 30 | Q16: =ROUNDUP(Q15*(1+0.1),0) -> 586 | R16: 30 | S16: =ROUNDUP(S15*(1+0.1),0) -> 893 | T16: 0 | U16: =ROUNDUP(U15*(1+$Z$16),0) -> 9299 | V16: =ROUNDDOWN(U16*2400/2400,0) -> 9299 | W16: 0 | Z16: 0.145 | AB16: =ROUNDUP(E16/$E$3,3) -> 8.028
A17: 15 | B17: 20 | C17: =ROUNDUP(C16*(1+$Z$16),0) -> 313 | D17: 22 | E17: =ROUNDUP(E16*(1+$Z$16),0) -> 341 | F17: 24 | G17: =ROUNDUP(G16*(1+$Z$16),0) -> 567 | H17: 26 | I17: =ROUNDUP(I16*(1+$Z$16),0) -> 799 | J17: 28 | K17: =ROUNDUP(K16*(1+$Z$16),0) -> 1088 | L17: 30 | M17: =ROUNDUP(M16*(1+0.1),0) -> 403 | N17: 30 | O17: =ROUNDUP(O16*(1+0.1),0) -> 602 | P17: 30 | Q17: =ROUNDUP(Q16*(1+0.1),0) -> 645 | R17: 30 | S17: =ROUNDUP(S16*(1+0.1),0) -> 983 | T17: 0 | U17: =ROUNDUP(U16*(1+$Z$16),0) -> 10648 | V17: =ROUNDDOWN(U17*2400/2400,0) -> 10648 | W17: 1 | X17: =V17*2 -> 21296 | Z17: =天赋设定!F69*20 -> 21960.175 | AB17: =ROUNDUP(E17/$E$3,3) -> 9.217
A18: 16 | B18: 20 | C18: =ROUNDDOWN((天赋设定!F65*30)*0.7/$B$3,0) -> 358 | D18: 22 | E18: =ROUNDDOWN((天赋设定!F66*30)*0.7/D18,0) -> 380 | F18: 24 | G18: =ROUNDDOWN((天赋设定!F67*30)*0.7/$B$3,0) -> 636 | H18: 26 | I18: =ROUNDDOWN((天赋设定!F68*30)*0.7/$B$3,0) -> 845 | J18: 28 | K18: =ROUNDDOWN((天赋设定!F69*30)*0.7/$B$3,0) -> 1152 | L18: 30 | M18: =ROUNDUP(M17*(1+0.1),0) -> 444 | N18: 30 | O18: =ROUNDUP(O17*(1+0.1),0) -> 663 | P18: 30 | Q18: =ROUNDUP(Q17*(1+0.1),0) -> 710 | R18: 30 | S18: =ROUNDUP(S17*(1+0.1),0) -> 1082 | T18: 2 | U18: =(K18*J18/2)*0.7 -> 11289.6 | V18: =ROUNDDOWN(U18*2400/2400,0) -> 11289 | W18: 0 | AB18: =ROUNDUP(E18/$E$3,3) -> 10.271
A19: 17 | B19: 20 | C19: =ROUNDUP(C18*(1+$Z$21),0) -> 398 | D19: 22 | E19: =ROUNDUP(E18*(1+$Z$21),0) -> 422 | F19: 24 | G19: =ROUNDUP(G18*(1+$Z$21),0) -> 706 | H19: 26 | I19: =ROUNDUP(I18*(1+$Z$21),0) -> 938 | J19: 28 | K19: =ROUNDUP(K18*(1+$Z$21),0) -> 1279 | L19: 30 | M19: =ROUNDUP(M18*(1+0.1),0) -> 489 | N19: 30 | O19: =ROUNDUP(O18*(1+0.1),0) -> 730 | P19: 30 | Q19: =ROUNDUP(Q18*(1+0.1),0) -> 781 | R19: 30 | S19: =ROUNDUP(S18*(1+0.1),0) -> 1191 | T19: 2 | U19: =ROUNDUP(U18*(1+$Z$21),0) -> 12532 | V19: =ROUNDDOWN(U19*2400/2400,0) -> 12532 | W19: 0 | AB19: =ROUNDUP(E19/$E$3,3) -> 11.406
A20: 18 | B20: 20 | C20: =ROUNDUP(C19*(1+$Z$21),0) -> 442 | D20: 22 | E20: =ROUNDUP(E19*(1+$Z$21),0) -> 469 | F20: 24 | G20: =ROUNDUP(G19*(1+$Z$21),0) -> 784 | H20: 26 | I20: =ROUNDUP(I19*(1+$Z$21),0) -> 1042 | J20: 28 | K20: =ROUNDUP(K19*(1+$Z$21),0) -> 1420 | L20: 30 | M20: =ROUNDUP(M19*(1+0.1),0) -> 538 | N20: 30 | O20: =ROUNDUP(O19*(1+0.1),0) -> 803 | P20: 30 | Q20: =ROUNDUP(Q19*(1+0.1),0) -> 860 | R20: 30 | S20: =ROUNDUP(S19*(1+0.1),0) -> 1311 | T20: 2 | U20: =ROUNDUP(U19*(1+$Z$21),0) -> 13911 | V20: =ROUNDDOWN(U20*2400/2400,0) -> 13911 | W20: 0 | AB20: =ROUNDUP(E20/$E$3,3) -> 12.676
A21: 19 | B21: 20 | C21: =ROUNDUP(C20*(1+$Z$21),0) -> 491 | D21: 22 | E21: =ROUNDUP(E20*(1+$Z$21),0) -> 521 | F21: 24 | G21: =ROUNDUP(G20*(1+$Z$21),0) -> 871 | H21: 26 | I21: =ROUNDUP(I20*(1+$Z$21),0) -> 1157 | J21: 28 | K21: =ROUNDUP(K20*(1+$Z$21),0) -> 1577 | L21: 30 | M21: =ROUNDUP(M20*(1+0.1),0) -> 592 | N21: 30 | O21: =ROUNDUP(O20*(1+0.1),0) -> 884 | P21: 30 | Q21: =ROUNDUP(Q20*(1+0.1),0) -> 946 | R21: 30 | S21: =ROUNDUP(S20*(1+0.1),0) -> 1443 | T21: 2 | U21: =ROUNDUP(U20*(1+$Z$21),0) -> 15442 | V21: =ROUNDDOWN(U21*2400/2400,0) -> 15442 | W21: 0 | Z21: 0.11 | AB21: =ROUNDUP(E21/$E$3,3) -> 14.082
A22: 20 | B22: 20 | C22: =ROUNDUP(C21*(1+$Z$21),0) -> 546 | D22: 22 | E22: =ROUNDUP(E21*(1+$Z$21),0) -> 579 | F22: 24 | G22: =ROUNDUP(G21*(1+$Z$21),0) -> 967 | H22: 26 | I22: =ROUNDUP(I21*(1+$Z$21),0) -> 1285 | J22: 28 | K22: =ROUNDUP(K21*(1+$Z$21),0) -> 1751 | L22: 30 | M22: =ROUNDUP(M21*(1+0.1),0) -> 652 | N22: 30 | O22: =ROUNDUP(O21*(1+0.1),0) -> 973 | P22: 30 | Q22: =ROUNDUP(Q21*(1+0.1),0) -> 1041 | R22: 30 | S22: =ROUNDUP(S21*(1+0.1),0) -> 1588 | T22: 0 | U22: =ROUNDUP(U21*(1+$Z$21),0) -> 17141 | V22: =ROUNDDOWN(U22*2400/2400,0) -> 17141 | W22: 1 | X22: =V22*2 -> 34282 | Z22: =天赋设定!G69*20 -> 34861.135 | AB22: =ROUNDUP(E22/$E$3,3) -> 15.649
A23: 21 | B23: 20 | C23: =ROUNDDOWN((天赋设定!G65*30)*0.7/$B$3,0) -> 588 | D23: 22 | E23: =ROUNDDOWN((天赋设定!G66*30)*0.7/D23,0) -> 619 | F23: 24 | G23: =ROUNDDOWN((天赋设定!G67*30)*0.7/$B$3,0) -> 1034 | H23: 26 | I23: =ROUNDDOWN((天赋设定!G68*30)*0.7/$B$3,0) -> 1342 | J23: 28 | K23: =ROUNDDOWN((天赋设定!G69*30)*0.7/$B$3,0) -> 1830 | L23: 30 | M23: =ROUNDUP(M22*(1+0.1),0) -> 718 | N23: 30 | O23: =ROUNDUP(O22*(1+0.1),0) -> 1071 | P23: 30 | Q23: =ROUNDUP(Q22*(1+0.1),0) -> 1146 | R23: 30 | S23: =ROUNDUP(S22*(1+0.1),0) -> 1747 | T23: 2 | U23: =(K23*J23/2)*0.7 -> 17934 | V23: =ROUNDDOWN(U23*2400/2400,0) -> 17934 | W23: 0 | AB23: =ROUNDUP(E23/$E$3,3) -> 16.73
A24: 22 | B24: 20 | C24: =ROUNDUP(C23*(1+$Z$26),0) -> 671 | D24: 22 | E24: =ROUNDUP(E23*(1+$Z$26),0) -> 706 | F24: 24 | G24: =ROUNDUP(G23*(1+$Z$26),0) -> 1179 | H24: 26 | I24: =ROUNDUP(I23*(1+$Z$26),0) -> 1530 | J24: 28 | K24: =ROUNDUP(K23*(1+$Z$26),0) -> 2087 | L24: 30 | M24: =ROUNDUP(M23*(1+0.1),0) -> 790 | N24: 30 | O24: =ROUNDUP(O23*(1+0.1),0) -> 1179 | P24: 30 | Q24: =ROUNDUP(Q23*(1+0.1),0) -> 1261 | R24: 30 | S24: =ROUNDUP(S23*(1+0.1),0) -> 1922 | T24: 2 | U24: =ROUNDUP(U23*(1+$Z$26),0) -> 20445 | V24: =ROUNDDOWN(U24*2400/2400,0) -> 20445 | W24: 0 | AB24: =ROUNDUP(E24/$E$3,3) -> 19.082
A25: 23 | B25: 20 | C25: =ROUNDUP(C24*(1+$Z$26),0) -> 765 | D25: 22 | E25: =ROUNDUP(E24*(1+$Z$26),0) -> 805 | F25: 24 | G25: =ROUNDUP(G24*(1+$Z$26),0) -> 1345 | H25: 26 | I25: =ROUNDUP(I24*(1+$Z$26),0) -> 1745 | J25: 28 | K25: =ROUNDUP(K24*(1+$Z$26),0) -> 2380 | L25: 30 | M25: =ROUNDUP(M24*(1+0.1),0) -> 869 | N25: 30 | O25: =ROUNDUP(O24*(1+0.1),0) -> 1297 | P25: 30 | Q25: =ROUNDUP(Q24*(1+0.1),0) -> 1388 | R25: 30 | S25: =ROUNDUP(S24*(1+0.1),0) -> 2115 | T25: 2 | U25: =ROUNDUP(U24*(1+$Z$26),0) -> 23308 | V25: =ROUNDDOWN(U25*2400/2400,0) -> 23308 | W25: 0 | AB25: =ROUNDUP(E25/$E$3,3) -> 21.757
A26: 24 | B26: 20 | C26: =ROUNDUP(C25*(1+$Z$26),0) -> 873 | D26: 22 | E26: =ROUNDUP(E25*(1+$Z$26),0) -> 918 | F26: 24 | G26: =ROUNDUP(G25*(1+$Z$26),0) -> 1534 | H26: 26 | I26: =ROUNDUP(I25*(1+$Z$26),0) -> 1990 | J26: 28 | K26: =ROUNDUP(K25*(1+$Z$26),0) -> 2714 | L26: 30 | M26: =ROUNDUP(M25*(1+0.1),0) -> 956 | N26: 30 | O26: =ROUNDUP(O25*(1+0.1),0) -> 1427 | P26: 30 | Q26: =ROUNDUP(Q25*(1+0.1),0) -> 1527 | R26: 30 | S26: =ROUNDUP(S25*(1+0.1),0) -> 2327 | T26: 2 | U26: =ROUNDUP(U25*(1+$Z$26),0) -> 26572 | V26: =ROUNDDOWN(U26*2400/2400,0) -> 26572 | W26: 0 | Z26: 0.14 | AB26: =ROUNDUP(E26/$E$3,3) -> 24.811
A27: 25 | B27: 20 | C27: =ROUNDUP(C26*(1+$Z$26),0) -> 996 | D27: 22 | E27: =ROUNDUP(E26*(1+$Z$26),0) -> 1047 | F27: 24 | G27: =ROUNDUP(G26*(1+$Z$26),0) -> 1749 | H27: 26 | I27: =ROUNDUP(I26*(1+$Z$26),0) -> 2269 | J27: 28 | K27: =ROUNDUP(K26*(1+$Z$26),0) -> 3094 | L27: 30 | M27: =ROUNDUP(M26*(1+0.1),0) -> 1052 | N27: 30 | O27: =ROUNDUP(O26*(1+0.1),0) -> 1570 | P27: 30 | Q27: =ROUNDUP(Q26*(1+0.1),0) -> 1680 | R27: 30 | S27: =ROUNDUP(S26*(1+0.1),0) -> 2560 | T27: 0 | U27: =ROUNDUP(U26*(1+$Z$26),0) -> 30293 | V27: =ROUNDDOWN(U27*2400/2400,0) -> 30293 | W27: 1 | X27: =V27*2 -> 60586 | Z27: =天赋设定!H69*20 -> 61199.818 | AB27: =ROUNDUP(E27/$E$3,3) -> 28.298

Sheet 无尽模式怪物属性
A1: 波次 | B1: 怪物数量 | C1: 怪物血量 | D1: 精英怪数量 | E1: 精英怪血量 | F1: BOSS数量 | G1: BOSS血量
A2: 1 | B2: 30 | C2: 12
A3: 2 | B3: 30 | C3: =ROUNDUP($C$2*(1+0.1)^(A3-1),0) -> 14
A4: 3 | B4: 30 | C4: =ROUNDUP($C$2*(1+0.1)^(A4-1),0) -> 15
A5: 4 | B5: 30 | C5: =ROUNDUP($C$2*(1+0.1)^(A5-1),0) -> 16
A6: 5 | B6: 30 | C6: =ROUNDUP($C$2*(1+0.1)^(A6-1),0) -> 18 | D6: 2 | E6: =ROUNDDOWN(C6*B6/2,0) -> 270
A7: 6 | B7: 30 | C7: =ROUNDUP($C$2*(1+0.1)^(A7-1),0) -> 20
A8: 7 | B8: 30 | C8: =ROUNDUP($C$2*(1+0.1)^(A8-1),0) -> 22
A9: 8 | B9: 30 | C9: =ROUNDUP($C$2*(1+0.1)^(A9-1),0) -> 24
A10: 9 | B10: 30 | C10: =ROUNDUP($C$2*(1+0.1)^(A10-1),0) -> 26
A11: 10 | B11: 30 | C11: =ROUNDUP($C$2*(1+0.1)^(A11-1),0) -> 29 | F11: 1 | G11: =C11*B11 -> 870
A12: 11 | B12: 30 | C12: =ROUNDUP($C$2*(1+0.1)^(A12-1),0) -> 32
A13: 12 | B13: 30 | C13: =ROUNDUP($C$2*(1+0.1)^(A13-1),0) -> 35
A14: 13 | B14: 30 | C14: =ROUNDUP($C$2*(1+0.1)^(A14-1),0) -> 38
A15: 14 | B15: 30 | C15: =ROUNDUP($C$2*(1+0.1)^(A15-1),0) -> 42 | L15: 备注：刷新精英或BOSS时，不会刷新小怪，此处只是为了方便计算做了保留
A16: 15 | B16: 30 | C16: =ROUNDUP($C$2*(1+0.1)^(A16-1),0) -> 46 | D16: 2 | E16: =ROUNDDOWN(C16*B16/2,0) -> 690
A17: 16 | B17: 30 | C17: =ROUNDUP($C$2*(1+0.1)^(A17-1),0) -> 51
A18: 17 | B18: 30 | C18: =ROUNDUP($C$2*(1+0.1)^(A18-1),0) -> 56
A19: 18 | B19: 30 | C19: =ROUNDUP($C$2*(1+0.1)^(A19-1),0) -> 61
A20: 19 | B20: 30 | C20: =ROUNDUP($C$2*(1+0.1)^(A20-1),0) -> 67
A21: 20 | B21: 30 | C21: =ROUNDUP($C$2*(1+0.1)^(A21-1),0) -> 74 | F21: 1 | G21: =C21*B21 -> 2220
A22: 21 | B22: 30 | C22: =ROUNDUP($C$2*(1+0.1)^(A22-1),0) -> 81
A23: 22 | B23: 30 | C23: =ROUNDUP($C$2*(1+0.1)^(A23-1),0) -> 89
A24: 23 | B24: 30 | C24: =ROUNDUP($C$2*(1+0.1)^(A24-1),0) -> 98
A25: 24 | B25: 30 | C25: =ROUNDUP($C$2*(1+0.1)^(A25-1),0) -> 108
A26: 25 | B26: 30 | C26: =ROUNDUP($C$2*(1+0.1)^(A26-1),0) -> 119 | D26: 2 | E26: =ROUNDDOWN(C26*B26/2,0) -> 1785
A27: 26 | B27: 30 | C27: =ROUNDUP($C$2*(1+0.1)^(A27-1),0) -> 131
A28: 27 | B28: 30 | C28: =ROUNDUP($C$2*(1+0.1)^(A28-1),0) -> 144
A29: 28 | B29: 30 | C29: =ROUNDUP($C$2*(1+0.1)^(A29-1),0) -> 158
A30: 29 | B30: 30 | C30: =ROUNDUP($C$2*(1+0.1)^(A30-1),0) -> 174
A31: 30 | B31: 30 | C31: =ROUNDUP($C$2*(1+0.1)^(A31-1),0) -> 191 | F31: 1 | G31: =C31*B31 -> 5730
A32: 31 | B32: 30 | C32: =ROUNDUP($C$2*(1+0.1)^(A32-1),0) -> 210
A33: 32 | B33: 30 | C33: =ROUNDUP($C$2*(1+0.1)^(A33-1),0) -> 231
A34: 33 | B34: 30 | C34: =ROUNDUP($C$2*(1+0.1)^(A34-1),0) -> 254
A35: 34 | B35: 30 | C35: =ROUNDUP($C$2*(1+0.1)^(A35-1),0) -> 279
A36: 35 | B36: 30 | C36: =ROUNDUP($C$2*(1+0.1)^(A36-1),0) -> 307 | D36: 2 | E36: =ROUNDDOWN(C36*B36/2,0) -> 4605
A37: 36 | B37: 30 | C37: =ROUNDUP($C$2*(1+0.1)^(A37-1),0) -> 338
A38: 37 | B38: 30 | C38: =ROUNDUP($C$2*(1+0.1)^(A38-1),0) -> 371
A39: 38 | B39: 30 | C39: =ROUNDUP($C$2*(1+0.1)^(A39-1),0) -> 409
A40: 39 | B40: 30 | C40: =ROUNDUP($C$2*(1+0.1)^(A40-1),0) -> 449
...

Sheet 局内升级
A1: 升级次数/升级所需经验 | B1: 1 | C1: 2 | D1: 3 | E1: 4 | H1: 无尽模式 | I1: 关卡模式
A2: 1 | B2: =C2+C3 -> 684 | C2: =ROUNDDOWN(C3+(2400*2/8 - 250*2)/7,0) -> 349 | D2: =ROUNDDOWN(D3+(2400*2/12 - 150*2)/11,0) -> 249 | E2: =ROUNDDOWN(E3+(2400*2/16 - 100*2)/15,0) -> 195 | G2: 杀怪经验/只 | H2: 4 | I2: 25
A3: 2 | B3: =C4+C5 -> 628 | C3: =ROUNDDOWN(C4+(2400*2/8 - 250*2)/7,0) -> 335 | D3: =ROUNDDOWN(D4+(2400*2/12 - 150*2)/11,0) -> 240 | E3: =ROUNDDOWN(E4+(2400*2/16 - 100*2)/15,0) -> 189
A4: 3 | B4: =C6+C7 -> 572 | C4: =ROUNDDOWN(C5+(2400*2/8 - 250*2)/7,0) -> 321 | D4: =ROUNDDOWN(D5+(2400*2/12 - 150*2)/11,0) -> 231 | E4: =ROUNDDOWN(E5+(2400*2/16 - 100*2)/15,0) -> 183
A5: 4 | B5: =C8+C9 -> 516 | C5: =ROUNDDOWN(C6+(2400*2/8 - 250*2)/7,0) -> 307 | D5: =ROUNDDOWN(D6+(2400*2/12 - 150*2)/11,0) -> 222 | E5: =ROUNDDOWN(E6+(2400*2/16 - 100*2)/15,0) -> 177
A6: 5 | C6: =ROUNDDOWN(C7+(2400*2/8 - 250*2)/7,0) -> 293 | D6: =ROUNDDOWN(D7+(2400*2/12 - 150*2)/11,0) -> 213 | E6: =ROUNDDOWN(E7+(2400*2/16 - 100*2)/15,0) -> 171
A7: 6 | C7: =ROUNDDOWN(C8+(2400*2/8 - 250*2)/7,0) -> 279 | D7: =ROUNDDOWN(D8+(2400*2/12 - 150*2)/11,0) -> 204 | E7: =ROUNDDOWN(E8+(2400*2/16 - 100*2)/15,0) -> 165
A8: 7 | C8: =ROUNDDOWN(C9+(2400*2/8 - 250*2)/7,0) -> 265 | D8: =ROUNDDOWN(D9+(2400*2/12 - 150*2)/11,0) -> 195 | E8: =ROUNDDOWN(E9+(2400*2/16 - 100*2)/15,0) -> 159
A9: 8 | C9: 251 | D9: =ROUNDDOWN(D10+(2400*2/12 - 150*2)/11,0) -> 186 | E9: =ROUNDDOWN(E10+(2400*2/16 - 100*2)/15,0) -> 153
A10: 9 | D10: =ROUNDDOWN(D11+(2400*2/12 - 150*2)/11,0) -> 177 | E10: =ROUNDDOWN(E11+(2400*2/16 - 100*2)/15,0) -> 147
A11: 10 | D11: =ROUNDDOWN(D12+(2400*2/12 - 150*2)/11,0) -> 168 | E11: =ROUNDDOWN(E12+(2400*2/16 - 100*2)/15,0) -> 141
A12: 11 | D12: =ROUNDDOWN(D13+(2400*2/12 - 150*2)/11,0) -> 159 | E12: =ROUNDDOWN(E13+(2400*2/16 - 100*2)/15,0) -> 135
A13: 12 | D13: 150 | E13: =ROUNDDOWN(E14+(2400*2/16 - 100*2)/15,0) -> 129
A14: 13 | E14: =ROUNDDOWN(E15+(2400*2/16 - 100*2)/15,0) -> 123
A15: 14 | E15: =ROUNDDOWN(E16+(2400*2/16 - 100*2)/15,0) -> 117
A16: 15 | E16: =ROUNDDOWN(E17+(2400*2/16 - 100*2)/15,0) -> 111
A17: 16 | E17: 105

Sheet 金币收益
A1: 一局游戏时长/秒 | B1: 200
A2: 一局游戏杀怪金币收益 | B2: =(144+180)/2+((50+50)*4+100)/5 -> 262
A3: 一局游戏结算金币收益 | B3: =ROUNDUP((50*0.2+150*0.35+300*0.45),0) -> 198
A4: 设定玩家通关率为80%，则玩家每小时金币收益为 | B4: =(B2+B3)*0.8/B1*3600 -> 6624
